{
    "assignee": null,
    "assignees": [],
    "author_association": "NONE",
    "body": "Hi,\r\n\r\nI am using Cython 0.28.2 from Anaconda and noticed that the following code will lead to AssertionError during Cython compilation:\r\n\r\n```\r\ncdef struct B:\r\n    int a\r\n    int b\r\n\r\ncdef class A:\r\n    cdef const B[:] c\r\n```\r\n\r\n```\r\n% cythonize test.pyx\r\nCompiling test.pyx because it changed.\r\n[1/1] Cythonizing test.pyx\r\nTraceback (most recent call last):\r\n  File \"/home/zhanghj/.local/opt/conda/bin/cythonize\", line 11, in <module>\r\n    sys.exit(main())\r\n  File \"/home/zhanghj/.local/opt/conda/lib/python3.6/site-packages/Cython/Build/Cythonize.py\", line 196, in main\r\n    cython_compile(path, options)\r\n  File \"/home/zhanghj/.local/opt/conda/lib/python3.6/site-packages/Cython/Build/Cythonize.py\", line 90, in cython_compile\r\n    **options.options)\r\n  File \"/home/zhanghj/.local/opt/conda/lib/python3.6/site-packages/Cython/Build/Dependencies.py\", line 1026, in cythonize\r\n    cythonize_one(*args)\r\n  File \"/home/zhanghj/.local/opt/conda/lib/python3.6/site-packages/Cython/Build/Dependencies.py\", line 1129, in cythonize_one\r\n    result = compile_single(pyx_file, options, full_module_name=full_module_name)\r\n  File \"/home/zhanghj/.local/opt/conda/lib/python3.6/site-packages/Cython/Compiler/Main.py\", line 649, in compile_single\r\n    return run_pipeline(source, options, full_module_name)\r\n  File \"/home/zhanghj/.local/opt/conda/lib/python3.6/site-packages/Cython/Compiler/Main.py\", line 499, in run_pipeline\r\n    err, enddata = Pipeline.run_pipeline(pipeline, source)\r\n  File \"/home/zhanghj/.local/opt/conda/lib/python3.6/site-packages/Cython/Compiler/Pipeline.py\", line 354, in run_pipeline\r\n    data = run(phase, data)\r\n  File \"/home/zhanghj/.local/opt/conda/lib/python3.6/site-packages/Cython/Compiler/Pipeline.py\", line 334, in run\r\n    return phase(data)\r\n  File \"/home/zhanghj/.local/opt/conda/lib/python3.6/site-packages/Cython/Compiler/Pipeline.py\", line 52, in generate_pyx_code_stage\r\n    module_node.process_implementation(options, result)\r\n  File \"/home/zhanghj/.local/opt/conda/lib/python3.6/site-packages/Cython/Compiler/ModuleNode.py\", line 142, in process_implementation\r\n    self.generate_c_code(env, options, result)\r\n  File \"/home/zhanghj/.local/opt/conda/lib/python3.6/site-packages/Cython/Compiler/ModuleNode.py\", line 397, in generate_c_code\r\n    globalstate.use_utility_code(utilcode)\r\n  File \"Cython/Compiler/Code.py\", line 1601, in Cython.Compiler.Code.GlobalState.use_utility_code\r\n  File \"Cython/Compiler/Code.py\", line 674, in Cython.Compiler.Code.LazyUtilityCode.put_code\r\n  File \"/home/zhanghj/.local/opt/conda/lib/python3.6/site-packages/Cython/Compiler/PyrexTypes.py\", line 888, in lazy_utility_callback\r\n    context['dtype_typeinfo'] = Buffer.get_type_information_cname(code, self.dtype)\r\n  File \"/home/zhanghj/.local/opt/conda/lib/python3.6/site-packages/Cython/Compiler/Buffer.py\", line 674, in get_type_information_cname\r\n    assert len(fields) > 0\r\nAssertionError\r\n```\r\n\r\n% cython --version\r\nCython version 0.28.2\r\n\r\n\r\nThank you",
    "closed_at": null,
    "comment_data": [
        {
            "author_association": "NONE",
            "body": "This is still an issue on 0.29.14. Attempting to assign anything to the memory view definition also generates the same error:\r\n\r\n```\r\nfrom struct import pack\r\n\r\ncdef packed struct B:\r\n    int a\r\n    int b\r\n    \r\ncdef const B[:] c\r\n\r\ncdef bytes data = pack('ii', 1, 2)\r\n# Adding this line will cause the assertion error. Any type of assignment seems to do it.\r\nc = data\r\n```\r\n",
            "created_at": "2019-12-28T23:20:31Z",
            "html_url": "https://github.com/cython/cython/issues/2251#issuecomment-569458680",
            "id": 569458680,
            "issue_url": "https://api.github.com/repos/cython/cython/issues/2251",
            "node_id": "MDEyOklzc3VlQ29tbWVudDU2OTQ1ODY4MA==",
            "updated_at": "2019-12-28T23:20:31Z",
            "url": "https://api.github.com/repos/cython/cython/issues/comments/569458680",
            "user": {
                "avatar_url": "https://avatars2.githubusercontent.com/u/13092253?v=4",
                "events_url": "https://api.github.com/users/brhumphe/events{/privacy}",
                "followers_url": "https://api.github.com/users/brhumphe/followers",
                "following_url": "https://api.github.com/users/brhumphe/following{/other_user}",
                "gists_url": "https://api.github.com/users/brhumphe/gists{/gist_id}",
                "gravatar_id": "",
                "html_url": "https://github.com/brhumphe",
                "id": 13092253,
                "login": "brhumphe",
                "node_id": "MDQ6VXNlcjEzMDkyMjUz",
                "organizations_url": "https://api.github.com/users/brhumphe/orgs",
                "received_events_url": "https://api.github.com/users/brhumphe/received_events",
                "repos_url": "https://api.github.com/users/brhumphe/repos",
                "site_admin": false,
                "starred_url": "https://api.github.com/users/brhumphe/starred{/owner}{/repo}",
                "subscriptions_url": "https://api.github.com/users/brhumphe/subscriptions",
                "type": "User",
                "url": "https://api.github.com/users/brhumphe"
            }
        }
    ],
    "comments": 1,
    "comments_url": "https://api.github.com/repos/cython/cython/issues/2251/comments",
    "created_at": "2018-05-09T10:39:46Z",
    "event_data": [],
    "events_url": "https://api.github.com/repos/cython/cython/issues/2251/events",
    "html_url": "https://github.com/cython/cython/issues/2251",
    "id": 321519330,
    "labels": [],
    "labels_url": "https://api.github.com/repos/cython/cython/issues/2251/labels{/name}",
    "locked": false,
    "milestone": null,
    "node_id": "MDU6SXNzdWUzMjE1MTkzMzA=",
    "number": 2251,
    "repository_url": "https://api.github.com/repos/cython/cython",
    "state": "open",
    "title": "Read-only memoryview fields in a cdef class lead to AssertionError",
    "updated_at": "2019-12-28T23:20:31Z",
    "url": "https://api.github.com/repos/cython/cython/issues/2251",
    "user": {
        "avatar_url": "https://avatars3.githubusercontent.com/u/14000695?v=4",
        "events_url": "https://api.github.com/users/zhanghjumich/events{/privacy}",
        "followers_url": "https://api.github.com/users/zhanghjumich/followers",
        "following_url": "https://api.github.com/users/zhanghjumich/following{/other_user}",
        "gists_url": "https://api.github.com/users/zhanghjumich/gists{/gist_id}",
        "gravatar_id": "",
        "html_url": "https://github.com/zhanghjumich",
        "id": 14000695,
        "login": "zhanghjumich",
        "node_id": "MDQ6VXNlcjE0MDAwNjk1",
        "organizations_url": "https://api.github.com/users/zhanghjumich/orgs",
        "received_events_url": "https://api.github.com/users/zhanghjumich/received_events",
        "repos_url": "https://api.github.com/users/zhanghjumich/repos",
        "site_admin": false,
        "starred_url": "https://api.github.com/users/zhanghjumich/starred{/owner}{/repo}",
        "subscriptions_url": "https://api.github.com/users/zhanghjumich/subscriptions",
        "type": "User",
        "url": "https://api.github.com/users/zhanghjumich"
    }
}