{
    "assignee": null,
    "assignees": [],
    "author_association": "NONE",
    "body": "Consider the following code:\r\n\r\n    def foo():\r\n        a = (1, 2)\r\n        a = (i for i in a)\r\n        next(a)\r\n        next(a)\r\n\r\n    foo()\r\n\r\nPython runs this fine (both v2 and v3), but with Cython, I am getting  `ValueError: generator already executing`. \r\n   \r\nI am using Cython version 0.28.4.",
    "closed_at": "2019-09-11T09:10:33Z",
    "comment_data": [
        {
            "author_association": "MEMBER",
            "body": "Duplicate of #1159.",
            "created_at": "2019-09-11T09:10:33Z",
            "html_url": "https://github.com/cython/cython/issues/3141#issuecomment-530293678",
            "id": 530293678,
            "issue_url": "https://api.github.com/repos/cython/cython/issues/3141",
            "node_id": "MDEyOklzc3VlQ29tbWVudDUzMDI5MzY3OA==",
            "updated_at": "2019-09-11T09:10:33Z",
            "url": "https://api.github.com/repos/cython/cython/issues/comments/530293678",
            "user": {
                "avatar_url": "https://avatars0.githubusercontent.com/u/491659?v=4",
                "events_url": "https://api.github.com/users/scoder/events{/privacy}",
                "followers_url": "https://api.github.com/users/scoder/followers",
                "following_url": "https://api.github.com/users/scoder/following{/other_user}",
                "gists_url": "https://api.github.com/users/scoder/gists{/gist_id}",
                "gravatar_id": "",
                "html_url": "https://github.com/scoder",
                "id": 491659,
                "login": "scoder",
                "node_id": "MDQ6VXNlcjQ5MTY1OQ==",
                "organizations_url": "https://api.github.com/users/scoder/orgs",
                "received_events_url": "https://api.github.com/users/scoder/received_events",
                "repos_url": "https://api.github.com/users/scoder/repos",
                "site_admin": false,
                "starred_url": "https://api.github.com/users/scoder/starred{/owner}{/repo}",
                "subscriptions_url": "https://api.github.com/users/scoder/subscriptions",
                "type": "User",
                "url": "https://api.github.com/users/scoder"
            }
        }
    ],
    "comments": 1,
    "comments_url": "https://api.github.com/repos/cython/cython/issues/3141/comments",
    "created_at": "2019-09-11T00:24:19Z",
    "event_data": [
        {
            "actor": {
                "avatar_url": "https://avatars0.githubusercontent.com/u/380854?v=4",
                "events_url": "https://api.github.com/users/bgedik/events{/privacy}",
                "followers_url": "https://api.github.com/users/bgedik/followers",
                "following_url": "https://api.github.com/users/bgedik/following{/other_user}",
                "gists_url": "https://api.github.com/users/bgedik/gists{/gist_id}",
                "gravatar_id": "",
                "html_url": "https://github.com/bgedik",
                "id": 380854,
                "login": "bgedik",
                "node_id": "MDQ6VXNlcjM4MDg1NA==",
                "organizations_url": "https://api.github.com/users/bgedik/orgs",
                "received_events_url": "https://api.github.com/users/bgedik/received_events",
                "repos_url": "https://api.github.com/users/bgedik/repos",
                "site_admin": false,
                "starred_url": "https://api.github.com/users/bgedik/starred{/owner}{/repo}",
                "subscriptions_url": "https://api.github.com/users/bgedik/subscriptions",
                "type": "User",
                "url": "https://api.github.com/users/bgedik"
            },
            "commit_id": null,
            "commit_url": null,
            "created_at": "2019-09-11T00:27:02Z",
            "event": "renamed",
            "id": 2624056210,
            "node_id": "MDE3OlJlbmFtZWRUaXRsZUV2ZW50MjYyNDA1NjIxMA==",
            "rename": {
                "from": "Cython produces 'ValueError: generator already executing' on code that Python runs file",
                "to": "Cython produces 'ValueError: generator already executing' on code that Python runs fine"
            },
            "url": "https://api.github.com/repos/cython/cython/issues/events/2624056210"
        },
        {
            "actor": {
                "avatar_url": "https://avatars0.githubusercontent.com/u/491659?v=4",
                "events_url": "https://api.github.com/users/scoder/events{/privacy}",
                "followers_url": "https://api.github.com/users/scoder/followers",
                "following_url": "https://api.github.com/users/scoder/following{/other_user}",
                "gists_url": "https://api.github.com/users/scoder/gists{/gist_id}",
                "gravatar_id": "",
                "html_url": "https://github.com/scoder",
                "id": 491659,
                "login": "scoder",
                "node_id": "MDQ6VXNlcjQ5MTY1OQ==",
                "organizations_url": "https://api.github.com/users/scoder/orgs",
                "received_events_url": "https://api.github.com/users/scoder/received_events",
                "repos_url": "https://api.github.com/users/scoder/repos",
                "site_admin": false,
                "starred_url": "https://api.github.com/users/scoder/starred{/owner}{/repo}",
                "subscriptions_url": "https://api.github.com/users/scoder/subscriptions",
                "type": "User",
                "url": "https://api.github.com/users/scoder"
            },
            "commit_id": null,
            "commit_url": null,
            "created_at": "2019-09-11T09:10:22Z",
            "event": "labeled",
            "id": 2624981027,
            "label": {
                "color": "444444",
                "name": "R: duplicate"
            },
            "node_id": "MDEyOkxhYmVsZWRFdmVudDI2MjQ5ODEwMjc=",
            "url": "https://api.github.com/repos/cython/cython/issues/events/2624981027"
        },
        {
            "actor": {
                "avatar_url": "https://avatars0.githubusercontent.com/u/491659?v=4",
                "events_url": "https://api.github.com/users/scoder/events{/privacy}",
                "followers_url": "https://api.github.com/users/scoder/followers",
                "following_url": "https://api.github.com/users/scoder/following{/other_user}",
                "gists_url": "https://api.github.com/users/scoder/gists{/gist_id}",
                "gravatar_id": "",
                "html_url": "https://github.com/scoder",
                "id": 491659,
                "login": "scoder",
                "node_id": "MDQ6VXNlcjQ5MTY1OQ==",
                "organizations_url": "https://api.github.com/users/scoder/orgs",
                "received_events_url": "https://api.github.com/users/scoder/received_events",
                "repos_url": "https://api.github.com/users/scoder/repos",
                "site_admin": false,
                "starred_url": "https://api.github.com/users/scoder/starred{/owner}{/repo}",
                "subscriptions_url": "https://api.github.com/users/scoder/subscriptions",
                "type": "User",
                "url": "https://api.github.com/users/scoder"
            },
            "commit_id": null,
            "commit_url": null,
            "created_at": "2019-09-11T09:10:33Z",
            "event": "closed",
            "id": 2624981702,
            "node_id": "MDExOkNsb3NlZEV2ZW50MjYyNDk4MTcwMg==",
            "url": "https://api.github.com/repos/cython/cython/issues/events/2624981702"
        }
    ],
    "events_url": "https://api.github.com/repos/cython/cython/issues/3141/events",
    "html_url": "https://github.com/cython/cython/issues/3141",
    "id": 491956589,
    "labels": [
        {
            "color": "444444",
            "default": false,
            "id": 425556894,
            "name": "R: duplicate",
            "node_id": "MDU6TGFiZWw0MjU1NTY4OTQ=",
            "url": "https://api.github.com/repos/cython/cython/labels/R:%20duplicate"
        }
    ],
    "labels_url": "https://api.github.com/repos/cython/cython/issues/3141/labels{/name}",
    "locked": false,
    "milestone": null,
    "node_id": "MDU6SXNzdWU0OTE5NTY1ODk=",
    "number": 3141,
    "repository_url": "https://api.github.com/repos/cython/cython",
    "state": "closed",
    "title": "Cython produces 'ValueError: generator already executing' on code that Python runs fine",
    "updated_at": "2019-09-11T09:10:34Z",
    "url": "https://api.github.com/repos/cython/cython/issues/3141",
    "user": {
        "avatar_url": "https://avatars0.githubusercontent.com/u/380854?v=4",
        "events_url": "https://api.github.com/users/bgedik/events{/privacy}",
        "followers_url": "https://api.github.com/users/bgedik/followers",
        "following_url": "https://api.github.com/users/bgedik/following{/other_user}",
        "gists_url": "https://api.github.com/users/bgedik/gists{/gist_id}",
        "gravatar_id": "",
        "html_url": "https://github.com/bgedik",
        "id": 380854,
        "login": "bgedik",
        "node_id": "MDQ6VXNlcjM4MDg1NA==",
        "organizations_url": "https://api.github.com/users/bgedik/orgs",
        "received_events_url": "https://api.github.com/users/bgedik/received_events",
        "repos_url": "https://api.github.com/users/bgedik/repos",
        "site_admin": false,
        "starred_url": "https://api.github.com/users/bgedik/starred{/owner}{/repo}",
        "subscriptions_url": "https://api.github.com/users/bgedik/subscriptions",
        "type": "User",
        "url": "https://api.github.com/users/bgedik"
    }
}