{
    "active_lock_reason": null,
    "assignee": null,
    "assignees": [],
    "author_association": "CONTRIBUTOR",
    "body": "### Describe the bug\n\n`cpp_stl_any.cast_test` is failing on i386 (32bit x86) in Debian's CI.\r\n\r\nLogs: https://ci.debian.net/packages/c/cython/\r\n\r\nThe cause isn't obvious so we'll skip the test, but I'm filing this so that someone can investigate more deeply.\n\n### Code to reproduce the behaviour:\n\n_No response_\n\n### Expected behaviour\n\n_No response_\n\n### OS\n\nLinux (Debian)\n\n### Python version\n\n3.12.1\n\n### Cython version\n\n3.0.6\n\n### Additional context\n\n```\r\n======================================================================\r\nFAIL: cast_test (cpp_stl_any)\r\nDoctest: cpp_stl_any.cast_test\r\n----------------------------------------------------------------------\r\nTraceback (most recent call last):\r\n  File \"/usr/lib/python3.12/doctest.py\", line 2247, in runTest\r\n    raise self.failureException(self.format_failure(new.getvalue()))\r\nAssertionError: Failed doctest test for cpp_stl_any.cast_test\r\n  File \"/tmp/autopkgtest-lxc.uq29_z3h/downtmp/autopkgtest_tmp/test-work-dir/1/run/cpp/cpp_stl_any/cpp_stl_any.cpython-312-i386-linux-gnu.so\", line unknown line number, in cast_test\r\n\r\n----------------------------------------------------------------------\r\nFile \"/tmp/autopkgtest-lxc.uq29_z3h/downtmp/autopkgtest_tmp/test-work-dir/1/run/cpp/cpp_stl_any/cpp_stl_any.cpython-312-i386-linux-gnu.so\", line ?, in cpp_stl_any.cast_test\r\nFailed example:\r\n    cast_test()\r\nException raised:\r\n    Traceback (most recent call last):\r\n      File \"/usr/lib/python3.12/doctest.py\", line 1359, in __run\r\n        exec(compile(example.source, filename, \"single\",\r\n      File \"<doctest cpp_stl_any.cast_test[0]>\", line 1, in <module>\r\n        cast_test()\r\n      File \"tests/run/cpp_stl_any.pyx\", line 44, in cpp_stl_any.cast_test (cpp_stl_any.cpp:2882)\r\n        assert any_cast[double](a) == 3.14\r\n    AssertionError\r\n\r\n\r\n======================================================================\r\nFAIL: cast_test (cpp_stl_any)\r\nDoctest: cpp_stl_any.cast_test\r\n----------------------------------------------------------------------\r\nTraceback (most recent call last):\r\n  File \"/usr/lib/python3.12/doctest.py\", line 2247, in runTest\r\n    raise self.failureException(self.format_failure(new.getvalue()))\r\nAssertionError: Failed doctest test for cpp_stl_any.cast_test\r\n  File \"/tmp/autopkgtest-lxc.uq29_z3h/downtmp/autopkgtest_tmp/test-work-dir/1/run/cpp/cpp_stl_any_directives_cpp_locals_True/cpp_stl_any.cpython-312-i386-linux-gnu.so\", line unknown line number, in cast_test\r\n\r\n----------------------------------------------------------------------\r\nFile \"/tmp/autopkgtest-lxc.uq29_z3h/downtmp/autopkgtest_tmp/test-work-dir/1/run/cpp/cpp_stl_any_directives_cpp_locals_True/cpp_stl_any.cpython-312-i386-linux-gnu.so\", line ?, in cpp_stl_any.cast_test\r\nFailed example:\r\n    cast_test()\r\nException raised:\r\n    Traceback (most recent call last):\r\n      File \"/usr/lib/python3.12/doctest.py\", line 1359, in __run\r\n        exec(compile(example.source, filename, \"single\",\r\n      File \"<doctest cpp_stl_any.cast_test[0]>\", line 1, in <module>\r\n        cast_test()\r\n      File \"tests/run/cpp_stl_any.pyx\", line 44, in cpp_stl_any.cast_test (cpp_stl_any.cpp:2882)\r\n        assert any_cast[double](a) == 3.14\r\n    AssertionError\r\n```",
    "closed_at": null,
    "comment_data": [],
    "comments": 0,
    "comments_url": "https://api.github.com/repos/cython/cython/issues/5928/comments",
    "created_at": "2023-12-28T13:56:32Z",
    "event_data": [],
    "events_url": "https://api.github.com/repos/cython/cython/issues/5928/events",
    "html_url": "https://github.com/cython/cython/issues/5928",
    "id": 2058471273,
    "labels": [],
    "labels_url": "https://api.github.com/repos/cython/cython/issues/5928/labels{/name}",
    "locked": false,
    "milestone": null,
    "node_id": "I_kwDOABDGAc56scdp",
    "number": 5928,
    "performed_via_github_app": null,
    "reactions": {
        "+1": 0,
        "-1": 0,
        "confused": 0,
        "eyes": 0,
        "heart": 0,
        "hooray": 0,
        "laugh": 0,
        "rocket": 0,
        "total_count": 0,
        "url": "https://api.github.com/repos/cython/cython/issues/5928/reactions"
    },
    "repository_url": "https://api.github.com/repos/cython/cython",
    "state": "open",
    "state_reason": null,
    "timeline_url": "https://api.github.com/repos/cython/cython/issues/5928/timeline",
    "title": "[BUG] test failure: cpp_stl_any.cast_test on i386 in Debian CI",
    "updated_at": "2023-12-28T13:56:32Z",
    "url": "https://api.github.com/repos/cython/cython/issues/5928",
    "user": {
        "avatar_url": "https://avatars.githubusercontent.com/u/442117?v=4",
        "events_url": "https://api.github.com/users/stefanor/events{/privacy}",
        "followers_url": "https://api.github.com/users/stefanor/followers",
        "following_url": "https://api.github.com/users/stefanor/following{/other_user}",
        "gists_url": "https://api.github.com/users/stefanor/gists{/gist_id}",
        "gravatar_id": "",
        "html_url": "https://github.com/stefanor",
        "id": 442117,
        "login": "stefanor",
        "node_id": "MDQ6VXNlcjQ0MjExNw==",
        "organizations_url": "https://api.github.com/users/stefanor/orgs",
        "received_events_url": "https://api.github.com/users/stefanor/received_events",
        "repos_url": "https://api.github.com/users/stefanor/repos",
        "site_admin": false,
        "starred_url": "https://api.github.com/users/stefanor/starred{/owner}{/repo}",
        "subscriptions_url": "https://api.github.com/users/stefanor/subscriptions",
        "type": "User",
        "url": "https://api.github.com/users/stefanor"
    }
}