{
    "active_lock_reason": null,
    "assignee": null,
    "assignees": [],
    "author_association": "CONTRIBUTOR",
    "body": "### Describe the bug\n\nThe coverage build of python-flint fails with current Cython master since commit ed2b40be6cad736ab39cffa2503d816ef2c6741e from gh-6144.\n\nIt always at the same point in the test suite with the same exception about thread.lock:\n```console\n$ PYTHONPATH=src coverage run -m flint.test\nRunning tests...\ntest_pyflint...OK\n...\ntest_polys...OK\ntest_mpolys...OK\ntest_fmpz_mpoly_vec...Exception ignored in: <_cython_3_1_0a0_mon.generator object at 0x71d86d8f03b0>\nTraceback (most recent call last):\n  File \"src/flint/types/fmpz_mpoly.pyx\", line 1274, in __iter__\n    yield z\n  File \"/stuff/current/active/python-flint/.venv313/lib/python3.13/site-packages/coverage/collector.py\", line 252, in lock_data\n    self.data_lock.acquire()\nSystemError: <method 'acquire' of '_thread.lock' objects> returned a result with an exception set\n```\nAt this point the process hangs, possibly in a deadlock or something. I can interrupt with Ctrl-C a few times which reveals a bit more traceback:\n```console\ntest_mpolys...OK\ntest_fmpz_mpoly_vec...Exception ignored in: <_cython_3_1_0a0_mon.generator object at 0x7463b4764460>\nTraceback (most recent call last):\n  File \"src/flint/types/fmpz_mpoly.pyx\", line 1274, in __iter__\n    yield z\n  File \"/stuff/current/active/python-flint/.venv313/lib/python3.13/site-packages/coverage/collector.py\", line 252, in lock_data\n    self.data_lock.acquire()\nSystemError: <method 'acquire' of '_thread.lock' objects> returned a result with an exception set\n^CTraceback (most recent call last):\n  File \"/stuff/current/active/python-flint/.venv313/lib/python3.13/site-packages/coverage/collector.py\", line 252, in lock_data\n    self.data_lock.acquire()\n    ~~~~~~~~~~~~~~~~~~~~~~^^\nKeyboardInterrupt\nException ignored in: 'flint.types.fmpz_mpoly.fmpz_mpoly.__dealloc__'\nTraceback (most recent call last):\n  File \"/stuff/current/active/python-flint/.venv313/lib/python3.13/site-packages/coverage/collector.py\", line 252, in lock_data\n    self.data_lock.acquire()\nKeyboardInterrupt: \n^CTraceback (most recent call last):\n  File \"/stuff/current/active/python-flint/.venv313/lib/python3.13/site-packages/coverage/collector.py\", line 252, in lock_data\n    self.data_lock.acquire()\n    ~~~~~~~~~~~~~~~~~~~~~~^^\nKeyboardInterrupt\nException ignored in: 'flint.types.fmpz_mpoly.fmpz_mpoly.__dealloc__'\nTraceback (most recent call last):\n  File \"/stuff/current/active/python-flint/.venv313/lib/python3.13/site-packages/coverage/collector.py\", line 252, in lock_data\n    self.data_lock.acquire()\nKeyboardInterrupt: \n^CTraceback (most recent call last):\n  File \"/stuff/current/active/python-flint/.venv313/lib/python3.13/site-packages/coverage/collector.py\", line 252, in lock_data\n    self.data_lock.acquire()\n    ~~~~~~~~~~~~~~~~~~~~~~^^\nKeyboardInterrupt\nException ignored in: 'flint.types.fmpz_mpoly.fmpz_mpoly_vec.__dealloc__'\nTraceback (most recent call last):\n  File \"/stuff/current/active/python-flint/.venv313/lib/python3.13/site-packages/coverage/collector.py\", line 252, in lock_data\n    self.data_lock.acquire()\nKeyboardInterrupt: \n^C^CTraceback (most recent call last):\n  File \"/stuff/current/active/python-flint/.venv313/lib/python3.13/site-packages/coverage/collector.py\", line 252, in lock_data\n    self.data_lock.acquire()\n    ~~~~~~~~~~~~~~~~~~~~~~^^\nKeyboardInterrupt\nException ignored in: 'flint.types.fmpz_mpoly.fmpz_mpoly.__dealloc__'\nTraceback (most recent call last):\n  File \"/stuff/current/active/python-flint/.venv313/lib/python3.13/site-packages/coverage/collector.py\", line 252, in lock_data\n    self.data_lock.acquire()\nKeyboardInterrupt: \n^CTraceback (most recent call last):\n  File \"/stuff/current/active/python-flint/.venv313/lib/python3.13/site-packages/coverage/cmdline.py\", line 858, in do_run\n    runner.run()\n    ~~~~~~~~~~^^\n  File \"/stuff/current/active/python-flint/.venv313/lib/python3.13/site-packages/coverage/execfile.py\", line 208, in run\n    exec(code, main_mod.__dict__)\n    ~~~~^^^^^^^^^^^^^^^^^^^^^^^^^\n  File \"/stuff/current/active/python-flint/src/flint/test/__main__.py\", line 137, in <module>\n    sys.exit(main(*sys.argv[1:]))\n             ~~~~^^^^^^^^^^^^^^^\n  File \"/stuff/current/active/python-flint/src/flint/test/__main__.py\", line 122, in main\n    success = run_all_tests(tests=tests, doctests=doctests, verbose=verbose)\n  File \"/stuff/current/active/python-flint/src/flint/test/__main__.py\", line 72, in run_all_tests\n    t_failed, t_total = run_tests(verbose=verbose)\n                        ~~~~~~~~~^^^^^^^^^^^^^^^^^\n  File \"/stuff/current/active/python-flint/src/flint/test/__main__.py\", line 37, in run_tests\n    test()\n    ~~~~^^\n  File \"/stuff/current/active/python-flint/src/flint/test/test_all.py\", line 3384, in test_fmpz_mpoly_vec\n    assert vec != mpoly_vec([x, x * y, ctx.from_dict({})], ctx)\n                                ~~^~~\n  File \"src/flint/flint_base/flint_base.pyx\", line 703, in flint.flint_base.flint_base.flint_mpoly.__mul__\n    def __mul__(self, other):\n  File \"/stuff/current/active/python-flint/.venv313/lib/python3.13/site-packages/coverage/collector.py\", line 252, in lock_data\n    self.data_lock.acquire()\n    ~~~~~~~~~~~~~~~~~~~~~~^^\nKeyboardInterrupt\n\nDuring handling of the above exception, another exception occurred:\n\nTraceback (most recent call last):\n  File \"/stuff/current/active/python-flint/.venv313/bin/coverage\", line 10, in <module>\n    sys.exit(main())\n             ~~~~^^\n  File \"/stuff/current/active/python-flint/.venv313/lib/python3.13/site-packages/coverage/cmdline.py\", line 970, in main\n    status = CoverageScript().command_line(argv)\n  File \"/stuff/current/active/python-flint/.venv313/lib/python3.13/site-packages/coverage/cmdline.py\", line 681, in command_line\n    return self.do_run(options, args)\n           ~~~~~~~~~~~^^^^^^^^^^^^^^^\n  File \"/stuff/current/active/python-flint/.venv313/lib/python3.13/site-packages/coverage/cmdline.py\", line 865, in do_run\n    self.coverage.save()\n    ~~~~~~~~~~~~~~~~~~^^\n  File \"/stuff/current/active/python-flint/.venv313/lib/python3.13/site-packages/coverage/control.py\", line 789, in save\n    data = self.get_data()\n  File \"/stuff/current/active/python-flint/.venv313/lib/python3.13/site-packages/coverage/control.py\", line 869, in get_data\n    if self._collector.flush_data():\n       ~~~~~~~~~~~~~~~~~~~~~~~~~~^^\n  File \"/stuff/current/active/python-flint/.venv313/lib/python3.13/site-packages/coverage/collector.py\", line 496, in flush_data\n    self._clear_data()\n    ~~~~~~~~~~~~~~~~^^\n  File \"/stuff/current/active/python-flint/.venv313/lib/python3.13/site-packages/coverage/collector.py\", line 196, in _clear_data\n    with self.data_lock or contextlib.nullcontext():\n         ^^^^^^^^^^^^^^^^^^^^^^^^^^^^^^^^^^^^^^^^^^\nKeyboardInterrupt\n```\n\nThe specific line of Cython code at which this happens is:\nhttps://github.com/flintlib/python-flint/blob/292fa0d51e2a59c15fd757e15fd5687526496dad/src/flint/types/fmpz_mpoly.pyx#L1274\n\nThere are not many places in the codebase that actually use `yield` in the Cython code i.e. not many generator functions so this is possibly just the first occurrence of a generator function in the test suite.\n\nThe problem only arises when:\n\n- Using Python 3.13 (earlier versions are fine)\n- Building with Cython after commit ed2b40be6cad736ab39cffa2503d816ef2c6741e\n- Using a coverage enabled build of the Cython modules (`CYTHON_TRACE=1`, `linetrace=True`).\n- Running the tests under `coverage`.\n\nThis works fine:\n```\npython -m flint.test\n```\nHowever this fails with `SystemError` at the `yield` as shown above:\n```\ncoverage run -m flint.test\n```\nRunning under `coverage` works fine though if not using the `CYTHON_TRACE` and `linetrace` options i.e. when not using a coverage enabled build.\n\nI see that there is https://github.com/nedbat/coveragepy/issues/1790 which says that coverage will disable Cython's coverage plugin. Note though that I see this failure when running under coverage even if not actually using any coverage plugin.\n\n### Code to reproduce the behaviour:\n\nI have not distilled this to a simple reproducer but I imagine that something involving generator functions will do it.\n\n### Expected behaviour\n\n_No response_\n\n### OS\n\nLinux and I think I also saw it on MacOS as well previously\n\n### Python version\n\n3.13 (earlier versions are fine)\n\n### Cython version\n\n`3.1.0a1+` (versions `<=3.0.11` are fine).\n\n### Additional context\n\n_No response_",
    "closed_at": null,
    "closed_by": null,
    "comment_data": [],
    "comments": 0,
    "comments_url": "https://api.github.com/repos/cython/cython/issues/6658/comments",
    "created_at": "2025-02-07T18:40:08Z",
    "event_data": [],
    "events_url": "https://api.github.com/repos/cython/cython/issues/6658/events",
    "html_url": "https://github.com/cython/cython/issues/6658",
    "id": 2838835812,
    "labels": [],
    "labels_url": "https://api.github.com/repos/cython/cython/issues/6658/labels{/name}",
    "locked": false,
    "milestone": null,
    "node_id": "I_kwDOABDGAc6pNTJk",
    "number": 6658,
    "performed_via_github_app": null,
    "reactions": {
        "+1": 0,
        "-1": 0,
        "confused": 0,
        "eyes": 0,
        "heart": 0,
        "hooray": 0,
        "laugh": 0,
        "rocket": 0,
        "total_count": 0,
        "url": "https://api.github.com/repos/cython/cython/issues/6658/reactions"
    },
    "repository_url": "https://api.github.com/repos/cython/cython",
    "state": "open",
    "state_reason": null,
    "sub_issues_summary": {
        "completed": 0,
        "percent_completed": 0,
        "total": 0
    },
    "timeline_url": "https://api.github.com/repos/cython/cython/issues/6658/timeline",
    "title": "[BUG] Running under coverage with 3.13 fails at yield with SystemError thread.lock",
    "updated_at": "2025-02-07T18:40:08Z",
    "url": "https://api.github.com/repos/cython/cython/issues/6658",
    "user": {
        "avatar_url": "https://avatars.githubusercontent.com/u/1159732?v=4",
        "events_url": "https://api.github.com/users/oscarbenjamin/events{/privacy}",
        "followers_url": "https://api.github.com/users/oscarbenjamin/followers",
        "following_url": "https://api.github.com/users/oscarbenjamin/following{/other_user}",
        "gists_url": "https://api.github.com/users/oscarbenjamin/gists{/gist_id}",
        "gravatar_id": "",
        "html_url": "https://github.com/oscarbenjamin",
        "id": 1159732,
        "login": "oscarbenjamin",
        "node_id": "MDQ6VXNlcjExNTk3MzI=",
        "organizations_url": "https://api.github.com/users/oscarbenjamin/orgs",
        "received_events_url": "https://api.github.com/users/oscarbenjamin/received_events",
        "repos_url": "https://api.github.com/users/oscarbenjamin/repos",
        "site_admin": false,
        "starred_url": "https://api.github.com/users/oscarbenjamin/starred{/owner}{/repo}",
        "subscriptions_url": "https://api.github.com/users/oscarbenjamin/subscriptions",
        "type": "User",
        "url": "https://api.github.com/users/oscarbenjamin",
        "user_view_type": "public"
    }
}